from django import forms
from django.contrib.auth.forms import UserCreationForm
from django.contrib.auth.models import User
from django.core.exceptions import ValidationError


class CustomUserCreationForm(UserCreationForm):
    username = forms.CharField(label='username', min_length=5, max_length=150)
    first_name = forms.CharField(label='first_name', min_length=5, max_length=150)
    last_name = forms.CharField(label='last_name', min_length=5, max_length=150)
    email = forms.EmailField(label='email')
    password1 = forms.CharField(label='password', widget=forms.PasswordInput)
    password2 = forms.CharField(label='Confirm password', widget=forms.PasswordInput)


    def username_clean(self):
        username = self.cleaned_data.get('username')
        new = User.objects.filter(username=username)
        if new.count():
            raise ValidationError('Username already exists')
        return username

    def email_clean(self):
        email = self.cleaned_data['email'].lower()
        new = User.objects.filter(email=email)
        if new.count():
            raise ValidationError('Email already exists')
        return email

    def clean_password2(self):
        password1 = self.cleaned_data['password1']
        password2 = self.cleaned_data['password2']

        if password1 and password2 and password1 != password2:
            raise ValidationError('Passwords do not match')
        return password2

    def save(self, commit=True):
        user = User.objects.create_user(
            username=self.cleaned_data['username'],
            email=self.cleaned_data['email'],
            password=self.cleaned_data['password1'],
            first_name=self.cleaned_data['first_name'],
            last_name=self.cleaned_data['last_name'],
        )
        return user
